{
  "timestamp": "2025-10-05T18:33:13.947693",
  "environment": "staging",
  "phases": {
    "phase1_environment": {
      "checks": [
        {
          "name": "Docker Services",
          "status": "passed",
          "details": {
            "total": 4,
            "running": 4,
            "stopped": 0
          }
        },
        {
          "name": "Redis",
          "status": "passed"
        },
        {
          "name": "Neo4j",
          "status": "passed"
        },
        {
          "name": "Postgres",
          "status": "passed"
        }
      ],
      "status": "passed"
    },
    "phase2_unit_tests": {
      "checks": [
        {
          "name": "Unit Tests",
          "status": "warning",
          "output": ".pytest.org/en/stable/deprecations.html#sync-test-depending-on-async-fixture\n    warnings.warn(\n\ntests/integration/test_phase2a_integration.py::TestPhase2AIntegration::test_crisis_intervention_workflow\n  /home/thein/recovered-tta-storytelling/.venv/lib/python3.12/site-packages/pytest_asyncio/plugin.py:678: PytestDeprecationWarning: asyncio test 'test_crisis_intervention_workflow' requested async @pytest.fixture 'setup_test_environment' in strict mode. You might want to use @pytest_asyncio.fixture or switch to auto mode. This will become an error in future versions of pytest-asyncio.\n    warnings.warn(\n\n-- Docs: https://docs.pytest.org/en/stable/how-to/capture-warnings.html\n=========================== short test summary info ============================\nFAILED tests/integration/test_core_gameplay_loop.py::TestCoreGameplayLoopIntegration::test_complete_gameplay_session_flow\nFAILED tests/integration/test_core_gameplay_loop.py::TestCoreGameplayLoopIntegration::test_therapeutic_progression_validation\nFAILED tests/integration/test_core_gameplay_loop.py::TestCoreGameplayLoopIntegration::test_emotional_state_adaptation\nFAILED tests/integration/test_core_gameplay_loop.py::TestCoreGameplayLoopIntegration::test_session_lifecycle_management\nFAILED tests/integration/test_phase2a_integration.py::TestPhase2AIntegration::test_patient_interface_integration\nFAILED tests/integration/test_phase2a_integration.py::TestPhase2AIntegration::test_living_worlds_integration\nFAILED tests/integration/test_phase2a_integration.py::TestPhase2AIntegration::test_ai_workflow_integration\nFAILED tests/integration/test_phase2a_integration.py::TestPhase2AIntegration::test_clinical_dashboard_integration\nFAILED tests/integration/test_phase2a_integration.py::TestPhase2AIntegration::test_therapeutic_systems_integration\nFAILED tests/integration/test_phase2a_integration.py::TestPhase2AIntegration::test_crisis_intervention_workflow\n!!!!!!!!!!!!!!!!!!!!!!!!!! stopping after 10 failures !!!!!!!!!!!!!!!!!!!!!!!!!!\n",
          "errors": ""
        }
      ],
      "status": "warning"
    },
    "phase3_integration_tests": {
      "checks": [
        {
          "name": "Integration Tests",
          "status": "warning",
          "output": "n/test_phase2a_integration.py::TestPhase2AIntegration::test_patient_interface_integration\n  /home/thein/recovered-tta-storytelling/.venv/lib/python3.12/site-packages/_pytest/fixtures.py:1182: PytestRemovedIn9Warning: 'test_patient_interface_integration' requested an async fixture 'setup_test_environment', with no plugin or hook that handled it. This is usually an error, as pytest does not natively support it. This will turn into an error in pytest 9.\n  See: https://docs.pytest.org/en/stable/deprecations.html#sync-test-depending-on-async-fixture\n    warnings.warn(\n\ntests/integration/test_phase2a_integration.py::TestPhase2AIntegration::test_patient_interface_integration\n  /home/thein/recovered-tta-storytelling/.venv/lib/python3.12/site-packages/pytest_asyncio/plugin.py:678: PytestDeprecationWarning: asyncio test 'test_patient_interface_integration' requested async @pytest.fixture 'setup_test_environment' in strict mode. You might want to use @pytest_asyncio.fixture or switch to auto mode. This will become an error in future versions of pytest-asyncio.\n    warnings.warn(\n\n-- Docs: https://docs.pytest.org/en/stable/how-to/capture-warnings.html\n=========================== short test summary info ============================\nFAILED tests/integration/test_core_gameplay_loop.py::TestCoreGameplayLoopIntegration::test_complete_gameplay_session_flow\nFAILED tests/integration/test_core_gameplay_loop.py::TestCoreGameplayLoopIntegration::test_therapeutic_progression_validation\nFAILED tests/integration/test_core_gameplay_loop.py::TestCoreGameplayLoopIntegration::test_emotional_state_adaptation\nFAILED tests/integration/test_core_gameplay_loop.py::TestCoreGameplayLoopIntegration::test_session_lifecycle_management\nFAILED tests/integration/test_phase2a_integration.py::TestPhase2AIntegration::test_patient_interface_integration\n!!!!!!!!!!!!!!!!!!!!!!!!!! stopping after 5 failures !!!!!!!!!!!!!!!!!!!!!!!!!!!\n================== 5 failed, 29 passed, 59 warnings in 25.81s ==================\n",
          "errors": ""
        }
      ],
      "status": "warning"
    },
    "phase4_code_quality": {
      "checks": [
        {
          "name": "Ruff Linting",
          "status": "warning",
          "issues": 81,
          "sample": "src/agent_orchestration/tools/models.py:92:1: E402 Module level import not at top of file\nsrc/agent_orchestration/workflow_manager.py:10:1: I001 [*] Import block is un-sorted or un-formatted\nsrc/components/agent_orchestration_component.py:987:24: B025 try-except block with duplicate exception `Exception`\nsrc/components/character_arc_integration.py:30:9: F401 `core.character_development_system.PersonalityTrait` imported but unused; consider using `importlib.util.find_spec` to test for availabilit"
        }
      ],
      "status": "passed"
    }
  },
  "summary": {
    "total_checks": 7,
    "passed": 4,
    "failed": 0,
    "warnings": 3,
    "overall_status": "PASS_WITH_WARNINGS"
  }
}